<?xml version="1.0" encoding="utf-8"?>
<!-- =================================================================================== -->
<!-- |    This document was autogenerated by xacro from 01-robot_biele.xacro           | -->
<!-- |    EDITING THIS FILE BY HAND IS NOT RECOMMENDED                                 | -->
<!-- =================================================================================== -->
<robot name="my_robot">
  <!--SECTION PRINCIPALE-->
  <link name="base_link">
    <visual>
      <origin rpy="0.0 0.0 0.0" xyz="-0.041 -0.064 -0.01388"/>
      <geometry>
        <mesh filename="package://my_robot_description/meshes/batit.STL" scale="1 1 1"/>
      </geometry>
    </visual>
    <!--<inertial>
                
                <inertia ixx="216.440077" ixy="11.153975" ixz="37.585887"
                     iyy="198.151113" iyz="19.180359"
                     izz="149.961523" />
        </inertial>-->
  </link>
  <link name="roue_droite">
    <visual>
      <origin rpy="0 0.0 0.0" xyz="-0.01835 -0.0128 -0.01835"/>
      <geometry>
        <mesh filename="package:///my_robot_description/meshes/roue.STL" scale="1 1 1"/>
      </geometry>
    </visual>
    <collision>
      <origin rpy="1.57079632679 0.0 0.0" xyz="0.0 -0.0078 0.0"/>
      <geometry>
        <cylinder length="0.0156" radius="0.01835"/>
      </geometry>
    </collision>
    <!--Prise de la matrice d'inertie d'un cylindre, pour simplifier étant donné que la roue est très proche d'un cylindre-->
    <!--<xacro:cylinder_inertial mass="${masse_roue}" r="${roue_rayon}" h="${roue_epaisseur}"/>-->
  </link>
  <joint name="droite_wheel_joint" type="continuous">
    <origin xyz="0.0 -0.0723 0.0"/>
    <parent link="base_link"/>
    <child link="roue_droite"/>
    <axis xyz="0.0 1.0 0.0"/>
  </joint>
  <link name="roue_gauche">
    <visual>
      <origin rpy="3.14159265359 0.0 0.0" xyz="-0.01835 0.0128 0.01835"/>
      <geometry>
        <mesh filename="package:///my_robot_description/meshes/roue.STL" scale="1 1 1"/>
      </geometry>
    </visual>
    <collision>
      <origin rpy="1.57079632679 0.0 0.0" xyz="0.0 0.0078 0.0"/>
      <geometry>
        <cylinder length="0.0156" radius="0.01835"/>
      </geometry>
    </collision>
    <!--Prise de la matrice d'inertie d'un cylindre, pour simplifier étant donné que la roue est très proche d'un cylindre-->
    <!--<xacro:cylinder_inertial mass="${masse_roue}" r="${roue_rayon}" h="${roue_epaisseur}"/>-->
  </link>
  <joint name="gauche_wheel_joint" type="continuous">
    <origin xyz="0.0 0.0723 0.0"/>
    <parent link="base_link"/>
    <child link="roue_gauche"/>
    <axis xyz="0.0 1.0 0.0"/>
  </joint>
</robot>

